<?xml version="1.0"?>
<!-- created with Phobos 1.0.1 "Capricious Choutengan" -->
  <robot name="Kitchen_standard">

    <link name="base_link">
      <inertial>
        <origin xyz="0 0 0" rpy="0 0 0"/>
        <mass value="0.2"/>
        <inertia ixx="0.001" ixy="0" ixz="0" iyy="0.001" iyz="0" izz="0.001"/>
      </inertial>
      <visual name="mug_base">
        <origin xyz="0 0 0" rpy="0 0 0"/>
        <geometry>
          <mesh filename="package://Kitchen_standard/meshes/dae/Group1/mesh6/mesh6-geometry#mesh6-geometry.dae" scale="1.0 1.0 1.0"/>
        </geometry>
        <material name="material_0_0.001"/>
      </visual>
      <collision name="mug_base.col">
        <origin xyz="0 0 0" rpy="0 0 0"/>
        <geometry>
          <mesh filename="package://Kitchen_standard/meshes/dae/Group1/mesh6/mesh6-geometry#mesh6-geometry.001.dae" scale="1.0 1.0 1.0"/>
        </geometry>
      </collision>
    </link>

    <link name="lid_link">
      <inertial>
        <origin xyz="0 0 0" rpy="0 0 0"/>
        <mass value="0.001"/>
        <inertia ixx="0.001" ixy="0" ixz="0" iyy="0.001" iyz="0" izz="0.001"/>
      </inertial>
      <visual name="mug_lid">
        <origin xyz="-0.00559 -0.00117 0" rpy="0 0 0"/>
        <geometry>
          <mesh filename="package://Kitchen_standard/meshes/dae/Union1/mesh32/mesh32-geometry#mesh32-geometry.dae" scale="1.0 1.0 1.0"/>
        </geometry>
        <material name="material_0_0.005"/>
      </visual>
      <collision name="mug_lid.col">
        <origin xyz="-0.00559 -0.00117 0" rpy="0 0 0"/>
        <geometry>
          <mesh filename="package://Kitchen_standard/meshes/dae/Union1/mesh32/mesh32-geometry#mesh32-geometry.001.dae" scale="1.0 1.0 1.0"/>
        </geometry>
      </collision>
    </link>

    <link name="mug1_root">
      <inertial>
        <origin xyz="0 0 0" rpy="0 0 0"/>
        <mass value="0.001"/>
        <inertia ixx="0.001" ixy="0" ixz="0" iyy="0.001" iyz="0" izz="0.001"/>
      </inertial>
    </link>

    <link name="refridge_door1">
      <inertial>
        <origin xyz="0 0 0" rpy="0 0 0"/>
        <mass value="0.001"/>
        <inertia ixx="0.001" ixy="0" ixz="0" iyy="0.001" iyz="0" izz="0.001"/>
      </inertial>
      <visual name="Plane">
        <origin xyz="0.01807 0.38291 0" rpy="0 0 0"/>
        <geometry>
          <mesh filename="package://Kitchen_standard/meshes/dae/Plane.dae" scale="0.02785 0.43052 0.43052"/>
        </geometry>
        <material name="refridge_mat"/>
      </visual>
      <collision name="Plane.000">
        <origin xyz="0.01807 0.38291 0" rpy="0 0 0"/>
        <geometry>
          <mesh filename="package://Kitchen_standard/meshes/dae/Plane.002.dae" scale="1.0 1.0 1.0"/>
        </geometry>
      </collision>
    </link>

    <link name="refridge_door2">
      <inertial>
        <origin xyz="0 0 0" rpy="0 0 0"/>
        <mass value="0.001"/>
        <inertia ixx="0.001" ixy="0" ixz="0" iyy="0.001" iyz="0" izz="0.001"/>
      </inertial>
      <visual name="Plane.001">
        <origin xyz="0.01727 0.38288 0" rpy="0 0 0"/>
        <geometry>
          <mesh filename="package://Kitchen_standard/meshes/dae/Plane.001.dae" scale="0.02785 0.43052 0.43052"/>
        </geometry>
        <material name="refridge_mat"/>
      </visual>
      <collision name="Plane.001.000">
        <origin xyz="0.01727 0.38288 0" rpy="0 0 0"/>
        <geometry>
          <mesh filename="package://Kitchen_standard/meshes/dae/Plane.003.dae" scale="1.0 1.0 1.0"/>
        </geometry>
      </collision>
    </link>

    <link name="refridge_root">
      <inertial>
        <origin xyz="0 0 0" rpy="0 0 0"/>
        <mass value="120.0"/>
        <inertia ixx="0.001" ixy="0" ixz="0" iyy="0.001" iyz="0" izz="0.001"/>
      </inertial>
      <visual name="Cube">
        <origin xyz="0 0 0" rpy="0 0 3.14159"/>
        <geometry>
          <mesh filename="package://Kitchen_standard/meshes/dae/Cube.050.dae" scale="1.0 1.0 1.0"/>
        </geometry>
        <material name="refridge_mat"/>
      </visual>
      <collision name="Cube.000">
        <origin xyz="0 0 0" rpy="0 0 3.14159"/>
        <geometry>
          <mesh filename="package://Kitchen_standard/meshes/dae/Cube.052.dae" scale="1.0 1.0 1.0"/>
        </geometry>
      </collision>
    </link>

    <link name="root_standard">
      <inertial>
        <origin xyz="0 0 0" rpy="0 0 0"/>
        <mass value="0.001"/>
        <inertia ixx="0.001" ixy="0" ixz="0" iyy="0.001" iyz="0" izz="0.001"/>
      </inertial>
    </link>

    <joint name="joint_0" type="fixed">
      <origin xyz="0.00559 0.00117 0" rpy="0 0 0"/>
      <parent link="base_link"/>
      <child link="lid_link"/>
    </joint>

    <joint name="joint_1" type="fixed">
      <origin xyz="0 0 0" rpy="0 0 0"/>
      <parent link="mug1_root"/>
      <child link="base_link"/>
    </joint>

    <joint name="mug1_root" type="fixed">
      <origin xyz="0.90549 -0.43287 0.282" rpy="0 0 0"/>
      <parent link="root_standard"/>
      <child link="mug1_root"/>
    </joint>

    <joint name="refridge_door1" type="revolute">
      <origin xyz="0.39089 0.38707 -0.83983" rpy="0 0 3.14159"/>
      <parent link="refridge_root"/>
      <child link="refridge_door1"/>
      <axis xyz="0 0 1.0"/>
      <limit lower="0" upper="3.0" effort="0" velocity="0"/>
    </joint>

    <joint name="refridge_door2" type="revolute">
      <origin xyz="0.3901 0.38705 0.35533" rpy="0 0 3.14159"/>
      <parent link="refridge_root"/>
      <child link="refridge_door2"/>
      <axis xyz="0 0 1.0"/>
      <limit lower="0" upper="3.0" effort="0" velocity="0"/>
    </joint>

    <joint name="refridge_root" type="floating">
      <origin xyz="0.99853 2.9037 -0.09375" rpy="0 0 -3.14159"/>
      <parent link="root_standard"/>
      <child link="refridge_root"/>
    </joint>

    <material name="material_0_0.001">
      <color rgba="0 0 0.4 1.0"/>
    </material>

    <material name="material_0_0.005">
      <color rgba="0.04706 0.04706 0.04706 1.0"/>
    </material>

    <material name="refridge_mat">
      <color rgba="0.74096 0.7879 0.7879 1.0"/>
    </material>

  </robot>
