<?xml version="1.0"?>
<!-- created with Phobos 1.0.1 "Capricious Choutengan" -->
  <robot name="RobotRoom_static">

    <link name="RobotRoom_static">
      <inertial>
        <origin xyz="0 0 0" rpy="0 0 0"/>
        <mass value="0.001"/>
        <inertia ixx="0.001" ixy="0" ixz="0" iyy="0.001" iyz="0" izz="0.001"/>
      </inertial>
      <visual name="Cube">
        <origin xyz="0 0 0" rpy="0 0 0"/>
        <geometry>
          <box size="5.5 5.5 0.04"/>
        </geometry>
        <material name="Floor"/>
      </visual>
      <collision name="Cube">
        <origin xyz="0 0 0" rpy="0 0 0"/>
        <geometry>
          <box size="5.5 5.5 0.04"/>
        </geometry>
      </collision>
    </link>

    <link name="wall1">
      <inertial>
        <origin xyz="0 0 0" rpy="0 0 0"/>
        <mass value="0.001"/>
        <inertia ixx="0.001" ixy="0" ixz="0" iyy="0.001" iyz="0" izz="0.001"/>
      </inertial>
      <visual name="Cube.002">
        <origin xyz="0 0 0" rpy="0 0 0"/>
        <geometry>
          <box size="0.04 5.5 3.04"/>
        </geometry>
        <material name="WallMat"/>
      </visual>
      <collision name="Cube.002">
        <origin xyz="0 0 1.5" rpy="0 0 0"/>
        <geometry>
          <box size="0.04 5.5 3.04"/>
        </geometry>
      </collision>
    </link>

    <joint name="wall1" type="floating">
      <origin xyz="0 2.77 0" rpy="0 0 1.5708"/>
      <parent link="RobotRoom_static"/>
      <child link="wall1"/>
    </joint>

    <joint name="wall1.000" type="floating">
      <origin xyz="0 2.77 0" rpy="0 0 1.5708"/>
      <parent link="RobotRoom_static"/>
      <child link="wall1"/>
    </joint>

    <material name="Floor">
      <color rgba="0.64 0.64 0.64 1.0"/>
    </material>

    <material name="WallMat">
      <color rgba="0.64 0.64 0.64 1.0"/>
    </material>

  </robot>
